<?xml version="1.0" encoding="utf-8"?>

<robot name="KAPEX0_mockup_wo_hand_260513">
  <mujoco>
    <compiler meshdir="../meshes" discardvisual="false" balanceinertia="true" fusestatic="false" strippath="false"/>
    <option collision="predefined" cone="elliptic" jacobian="sparse" tolerance="1e-6" iterations="30" solver="CG" timestep="0.001"/>
  </mujoco>

  <!-- MATERIALS -->
  <material name="space_gray">
    <color rgba="0.741176 0.737255 0.760784 1"/>
  </material>
  <material name="black">
    <color rgba="0.094118 0.094118 0.098039 1"/>
  </material>
  <material name="silver">
    <color rgba="0.752941 0.752941 0.752941 1"/>
  </material>
  <material name="gray">
    <color rgba="0.501961 0.501961 0.501961 1"/>
  </material>

  <!-- PELVIS -->
  <link name="pelvis">
    <inertial>
      <origin xyz="0.004228 6.74E-05 0.03717" rpy="0 0 0"/>
      <mass value="6.804"/>
      <inertia ixx="0.057343" ixy="-5.217E-05" ixz="-0.0021205" iyy="0.02519" iyz="1.1869E-06" izz="0.067446"/>
    </inertial>
    <visual>
      <origin xyz="0 0 0" rpy="0 0 0"/>
      <geometry>
        <mesh filename="meshes/pelvis.STL"/>
      </geometry>
      <material name="black"/>
    </visual>
    <!-- <collision>
      <origin xyz="0 0 0" rpy="0 0 0"/>
      <geometry>
        <mesh filename="meshes/pelvis.STL"/>
      </geometry>
    </collision> -->
    <collision>
      <origin xyz="-0.01 0 0.025" rpy="1.5707963 0 0"/>
      <geometry>
        <cylinder radius="0.09" length="0.18"/>
      </geometry>
    </collision>
    <!-- <collision>
      <origin xyz="-0.01 0.09 0.025" rpy="1.5707963 0 0"/>
      <geometry>
        <sphere radius="0.09"/>
      </geometry>
    </collision> -->
    <!-- <collision>
      <origin xyz="-0.01 -0.09 0.025" rpy="1.5707963 0 0"/>
      <geometry>
        <sphere radius="0.09"/>
      </geometry>
    </collision> -->
  </link>
  <link name="pelvis_link_cover">
    <inertial>
      <origin xyz="0 0 0" rpy="0 0 0"/>
      <mass value="0.0001"/>
      <inertia ixx="1E-07" ixy="0" ixz="0" iyy="1E-07" iyz="0" izz="1E-07"/>
    </inertial>
    <visual>
      <origin xyz="0 0 0" rpy="0 0 0"/>
      <geometry>
        <mesh filename="meshes/pelvis_link_cover.STL"/>
      </geometry>
      <material name="space_gray"/>
    </visual>
  </link>
  <joint name="pelvis_joint_cover" type="fixed">
    <origin xyz="0 0 0" rpy="0 0 0"/>
    <parent link="pelvis"/>
    <child link="pelvis_link_cover"/>
  </joint>
  <link name="pelvis_link_cover_1">
    <inertial>
      <origin xyz="0 0 0" rpy="0 0 0"/>
      <mass value="0.0001"/>
      <inertia ixx="1E-07" ixy="0" ixz="0" iyy="1E-07" iyz="0" izz="1E-07"/>
    </inertial>
    <visual>
      <origin xyz="0 0 0" rpy="0 0 0"/>
      <geometry>
        <mesh filename="meshes/pelvis_link_cover_1.STL"/>
      </geometry>
      <material name="black"/>
    </visual>
  </link>
  <joint name="pelvis_joint_cover_1" type="fixed">
    <origin xyz="0 0 0" rpy="0 0 0"/>
    <parent link="pelvis"/>
    <child link="pelvis_link_cover_1"/>
  </joint>

  <!-- LEFT LEG -->
  <link name="left_hip_yaw_link">
    <inertial>
      <origin xyz="-0.007526 0.0024503 -0.062743" rpy="0 0 0"/>
      <mass value="2.322"/>
      <inertia ixx="0.0076606" ixy="4.2997E-05" ixz="0.00045512" iyy="0.0058876" iyz="0.0003866" izz="0.0038626"/>
    </inertial>
    <visual>
      <origin xyz="0 0 0" rpy="0 0 0"/>
      <geometry>
        <mesh filename="meshes/left_hip_yaw_link.STL"/>
      </geometry>
      <material name="black"/>
    </visual>
    <!-- <collision>
      <origin xyz="0 0 0" rpy="0 0 0"/>
      <geometry>
        <mesh filename="meshes/left_hip_yaw_link.STL"/>
      </geometry>
    </collision> -->
  </link>
  <joint name="left_hip_yaw_joint" type="revolute">
    <origin xyz="0.00021213 0.1005 0.00021215" rpy="0 0.7854 0"/>
    <parent link="pelvis"/>
    <child link="left_hip_yaw_link"/>
    <axis xyz="0 0 1"/>
    <limit lower="-0.34907" upper="0.7854" effort="100" velocity="8.1812"/>
  </joint>
  <link name="left_hip_roll_link">
    <inertial>
      <origin xyz="0.071966 -0.002406 -0.004282" rpy="0 0 0"/>
      <mass value="3.242"/>
      <inertia ixx="0.0061023" ixy="-0.00025086" ixz="0.0014614" iyy="0.012763" iyz="-5.998E-05" izz="0.010458"/>
    </inertial>
    <visual>
      <origin xyz="0 0 0" rpy="0 0 0"/>
      <geometry>
        <mesh filename="meshes/left_hip_roll_link.STL"/>
      </geometry>
      <material name="black"/>
    </visual>
    <!-- <collision>
      <origin xyz="0 0 0" rpy="0 0 0"/>
      <geometry>
        <mesh filename="meshes/left_hip_roll_link.STL"/>
      </geometry>
    </collision>-->
  </link>
  <joint name="left_hip_roll_joint" type="revolute">
    <origin xyz="0.021 0 -0.081" rpy="0 0 0"/>
    <parent link="left_hip_yaw_link"/>
    <child link="left_hip_roll_link"/>
    <axis xyz="1 0 0"/>
    <limit lower="-0.34907" upper="0.34907" effort="100" velocity="8.1812"/>
  </joint>
  <link name="left_hip_roll_link_cover">
    <inertial>
      <origin xyz="0 0 0" rpy="0 0 0"/>
      <mass value="0.0001"/>
      <inertia ixx="1E-07" ixy="0" ixz="0" iyy="1E-07" iyz="0" izz="1E-07"/>
    </inertial>
    <visual>
      <origin xyz="0 0 0" rpy="0 0 0"/>
      <geometry>
        <mesh filename="meshes/left_hip_roll_link_cover.STL"/>
      </geometry>
      <material name="space_gray"/>
    </visual>
  </link>
  <joint name="left_hip_roll_joint_cover" type="fixed">
    <origin xyz="0 0 0" rpy="0 0 0"/>
    <parent link="left_hip_roll_link"/>
    <child link="left_hip_roll_link_cover"/>
  </joint>
  <link name="left_hip_pitch_link">
    <inertial>
      <origin xyz="0.000979 0.006906 -0.13909" rpy="0 0 0"/>
      <mass value="5.485"/>
      <inertia ixx="0.04047" ixy="7.9534E-05" ixz="-0.0011742" iyy="0.041909" iyz="0.00067707" izz="0.015633"/>
    </inertial>
    <visual>
      <origin xyz="0 0 0" rpy="0 0 0"/>
      <geometry>
        <mesh filename="meshes/left_hip_pitch_link.STL"/>
      </geometry>
      <material name="black"/>
    </visual>
    <!-- <collision>
      <origin xyz="0 0 0" rpy="0 0 0"/>
      <geometry>
        <mesh filename="meshes/left_hip_pitch_link.STL"/>
      </geometry>
    </collision> -->
    <collision>
      <origin xyz="0 0 -0.13" rpy="0 0 0"/>
      <geometry>
        <cylinder radius="0.08" length="0.18"/>
      </geometry>
    </collision>
    <!-- <collision>
      <origin xyz="0 0 -0.04" rpy="0 0 0"/>
      <geometry>
        <sphere radius="0.08"/>
      </geometry>
    </collision> -->
    <!-- <collision>
      <origin xyz="0 0 -0.22" rpy="0 0 0"/>
      <geometry>
        <sphere radius="0.08"/>
      </geometry>
    </collision> -->
  </link>
  <joint name="left_hip_pitch_joint" type="revolute">
    <origin xyz="0.0932 0 0" rpy="0 -0.7854 0"/>
    <parent link="left_hip_roll_link"/>
    <child link="left_hip_pitch_link"/>
    <axis xyz="0 1 0"/>
    <limit lower="-1.5708" upper="0.5236" effort="300" velocity="4.5451"/>
  </joint>
  <link name="left_hip_pitch_link_cover">
    <inertial>
      <origin xyz="0 0 0" rpy="0 0 0"/>
      <mass value="0.0001"/>
      <inertia ixx="1E-07" ixy="0" ixz="0" iyy="1E-07" iyz="0" izz="1E-07"/>
    </inertial>
    <visual>
      <origin xyz="0 0 0" rpy="0 0 0"/>
      <geometry>
        <mesh filename="meshes/left_hip_pitch_link_cover.STL"/>
      </geometry>
      <material name="space_gray"/>
    </visual>
  </link>
  <joint name="left_hip_pitch_joint_cover" type="fixed">
    <origin xyz="0 0 0" rpy="0 0 0"/>
    <parent link="left_hip_pitch_link"/>
    <child link="left_hip_pitch_link_cover"/>
  </joint>
  <link name="left_hip_pitch_link_cover_1">
    <inertial>
      <origin xyz="0 0 0" rpy="0 0 0"/>
      <mass value="0.0001"/>
      <inertia ixx="1E-07" ixy="0" ixz="0" iyy="1E-07" iyz="0" izz="1E-07"/>
    </inertial>
    <visual>
      <origin xyz="0 0 0" rpy="0 0 0"/>
      <geometry>
        <mesh filename="meshes/left_hip_pitch_link_cover_1.STL"/>
      </geometry>
      <material name="black"/>
    </visual>
  </link>
  <joint name="left_hip_pitch_joint_cover_1" type="fixed">
    <origin xyz="0 0 0" rpy="0 0 0"/>
    <parent link="left_hip_pitch_link"/>
    <child link="left_hip_pitch_link_cover_1"/>
  </joint>
  <link name="left_knee_link">
    <inertial>
      <origin xyz="0.003115 0.001439 -0.095936" rpy="0 0 0"/>
      <mass value="4.891"/>
      <inertia ixx="0.048615" ixy="-0.00015312" ixz="-0.00151906" iyy="0.050859" iyz="-0.00014988" izz="0.006863"/>
    </inertial>
    <visual>
      <origin xyz="0 0 0" rpy="0 0 0"/>
      <geometry>
        <mesh filename="meshes/left_knee_link.STL"/>
      </geometry>
      <material name="black"/>
    </visual>
    <!-- <collision>
      <origin xyz="0 0 0" rpy="0 0 0"/>
      <geometry>
        <mesh filename="meshes/left_knee_link.STL"/>
      </geometry>
    </collision> -->
    <collision>
      <origin xyz="0 0 -0.20" rpy="0 0 0"/>
      <geometry>
        <cylinder radius="0.06" length="0.16"/>
      </geometry>
    </collision>
    <!-- <collision>
      <origin xyz="0 0 -0.12" rpy="0 0 0"/>
      <geometry>
        <sphere radius="0.06"/>
      </geometry>
    </collision> -->
    <!-- <collision>
      <origin xyz="0 0 -0.28" rpy="0 0 0"/>
      <geometry>
        <sphere radius="0.06"/>
      </geometry>
    </collision> -->
  </link>
  <joint name="left_knee_joint" type="revolute">
    <origin xyz="-0.0034097 -0.0026122 -0.345" rpy="0 0 0"/>
    <parent link="left_hip_pitch_link"/>
    <child link="left_knee_link"/>
    <axis xyz="0 1 0"/>
    <limit lower="0" upper="1.9199" effort="300" velocity="4.5451"/>
  </joint>
  <link name="left_knee_link_cover">
    <inertial>
      <origin xyz="0 0 0" rpy="0 0 0"/>
      <mass value="0.0001"/>
      <inertia ixx="1E-07" ixy="0" ixz="0" iyy="1E-07" iyz="0" izz="1E-07"/>
    </inertial>
    <visual>
      <origin xyz="0 0 0" rpy="0 0 0"/>
      <geometry>
        <mesh filename="meshes/left_knee_link_cover.STL"/>
      </geometry>
      <material name="space_gray"/>
    </visual>
  </link>
  <joint name="left_knee_joint_cover" type="fixed">
    <origin xyz="0 0 0" rpy="0 0 0"/>
    <parent link="left_knee_link"/>
    <child link="left_knee_link_cover"/>
  </joint>
  <link name="left_ankle_pitch_link">
    <inertial>
      <origin xyz="-0.013184 0.0005938 -0.015486" rpy="0 0 0"/>
      <mass value="0.3104"/>
      <inertia ixx="0.00028737" ixy="4.498E-08" ixz="0.00016682" iyy="0.00037779" iyz="3.845E-07" izz="0.00019837"/>
    </inertial>
    <visual>
      <origin xyz="0 0 0" rpy="0 0 0"/>
      <geometry>
        <mesh filename="meshes/left_ankle_pitch_link.STL"/>
      </geometry>
      <material name="silver"/>
    </visual>
    <!-- <collision>
      <origin xyz="0 0 0" rpy="0 0 0"/>
      <geometry>
        <mesh filename="meshes/left_ankle_pitch_link.STL"/>
      </geometry>
    </collision> -->
  </link>
  <joint name="left_ankle_pitch_joint" type="revolute">
    <origin xyz="0.030105 0 -0.33999" rpy="0 0 0"/>
    <parent link="left_knee_link"/>
    <child link="left_ankle_pitch_link"/>
    <axis xyz="0 1 0"/>
    <limit lower="-0.5236" upper="0.87267" effort="100" velocity="8.1812"/>
  </joint>
  <link name="left_ankle_roll_link">
    <inertial>
      <origin xyz="0.026276 0.0001407 -0.017729" rpy="0 0 0"/>
      <mass value="0.7451"/>
      <inertia ixx="0.0013206" ixy="-5.312E-06" ixz="0.00071901" iyy="0.0025287" iyz="1.69E-07" izz="0.0020281"/>
    </inertial>
    <visual>
      <origin xyz="0 0 0" rpy="0 0 0"/>
      <geometry>
        <mesh filename="meshes/left_ankle_roll_link.STL"/>
      </geometry>
      <material name="gray"/>
    </visual>
    <collision>
      <origin xyz="0 0 0" rpy="0 0 0"/>
      <geometry>
        <mesh filename="meshes/left_ankle_roll_collision_link.STL" scale="0.001 0.001 0.001"/>
      </geometry>
    </collision>
  </link>
  <joint name="left_ankle_roll_joint" type="revolute">
    <origin xyz="0 0 0" rpy="0 0.64549 0"/>
    <parent link="left_ankle_pitch_link"/>
    <child link="left_ankle_roll_link"/>
    <axis xyz="0 0 1"/>
    <limit lower="-0.34907" upper="0.34907" effort="100" velocity="8.1812"/>
  </joint>
  <link name="left_toe_pitch_link">
    <inertial>
      <origin xyz="0.0259024 -2.07E-05 -0.009958" rpy="0 0 0"/>
      <mass value="0.3163"/>
      <inertia ixx="0.0001951" ixy="1.918E-07" ixz="2.59612E-05" iyy="0.00026895" iyz="6.518E-09" izz="0.00040482"/>
    </inertial>
    <visual>
      <origin xyz="0 0 0" rpy="0 0 0"/>
      <geometry>
        <mesh filename="meshes/left_toe_pitch_link.STL"/>
      </geometry>
      <material name="black"/>
    </visual>
    <collision>
      <origin xyz="0 0 0" rpy="0 0 0"/>
      <geometry>
        <mesh filename="meshes/left_toe_pitch_collision_link.STL" scale="0.001 0.001 0.001"/>
      </geometry>
    </collision>
  </link>
  <joint name="left_toe_pitch_joint" type="revolute">
    <origin xyz="0.12007 -0.0010001 0.013573" rpy="0 -0.64549 0"/>
    <parent link="left_ankle_roll_link"/>
    <child link="left_toe_pitch_link"/>
    <axis xyz="0 1 0"/>
    <limit lower="-1.0472" upper="0.34907" effort="20" velocity="7.0384"/>
  </joint>
  <link name="left_toe_pitch_link_cover">
    <inertial>
      <origin xyz="0 0 0" rpy="0 0 0"/>
      <mass value="0.0001"/>
      <inertia ixx="1E-07" ixy="0" ixz="0" iyy="1E-07" iyz="0" izz="1E-07"/>
    </inertial>
    <visual>
      <origin xyz="0 0 0" rpy="0 0 0"/>
      <geometry>
        <mesh filename="meshes/left_toe_pitch_link_cover.STL"/>
      </geometry>
      <material name="space_gray"/>
    </visual>
  </link>
  <joint name="left_toe_pitch_joint_cover" type="fixed">
    <origin xyz="0 0 0" rpy="0 0 0"/>
    <parent link="left_toe_pitch_link"/>
    <child link="left_toe_pitch_link_cover"/>
  </joint>

  <!-- RIGHT LEG -->
  <link name="right_hip_yaw_link">
    <inertial>
      <origin xyz="-0.007526 -0.00245 -0.062743" rpy="0 0 0"/>
      <mass value="2.3221"/>
      <inertia ixx="0.0076606" ixy="-4.2998E-05" ixz="0.00045512" iyy="0.0058876" iyz="-0.0003866" izz="0.0038626"/>
    </inertial>
    <visual>
      <origin xyz="0 0 0" rpy="0 0 0"/>
      <geometry>
        <mesh filename="meshes/right_hip_yaw_link.STL"/>
      </geometry>
      <material name="black"/>
    </visual>
    <!-- <collision>
      <origin xyz="0 0 0" rpy="0 0 0"/>
      <geometry>
        <mesh filename="meshes/right_hip_yaw_link.STL"/>
      </geometry>
    </collision> -->
  </link>
  <joint name="right_hip_yaw_joint" type="revolute">
    <origin xyz="0.00021213 -0.1005 0.00021215" rpy="0 0.7854 0"/>
    <parent link="pelvis"/>
    <child link="right_hip_yaw_link"/>
    <axis xyz="0 0 1"/>
    <limit lower="-0.7854" upper="0.34907" effort="100" velocity="8.1812"/>
  </joint>
  <link name="right_hip_roll_link">
    <inertial>
      <origin xyz="0.07197 0.0024082 -0.0042821" rpy="0 0 0"/>
      <mass value="3.242"/>
      <inertia ixx="0.006102" ixy="0.00025015" ixz="0.0014613" iyy="0.012762" iyz="6.0029E-05" izz="0.010456"/>
    </inertial>
    <visual>
      <origin xyz="0 0 0" rpy="0 0 0"/>
      <geometry>
        <mesh filename="meshes/right_hip_roll_link.STL"/>
      </geometry>
      <material name="black"/>
    </visual>
    <!-- <collision>
      <origin xyz="0 0 0" rpy="0 0 0"/>
      <geometry>
        <mesh filename="meshes/right_hip_roll_link.STL"/>
      </geometry>
    </collision> -->
  </link>
  <joint name="right_hip_roll_joint" type="revolute">
    <origin xyz="0.021 0 -0.081" rpy="0 0 0"/>
    <parent link="right_hip_yaw_link"/>
    <child link="right_hip_roll_link"/>
    <axis xyz="1 0 0"/>
    <limit lower="-0.34907" upper="0.34907" effort="100" velocity="8.1812"/>
  </joint>
  <link name="right_hip_roll_link_cover">
    <inertial>
      <origin xyz="0 0 0" rpy="0 0 0"/>
      <mass value="0.0001"/>
      <inertia ixx="1E-07" ixy="0" ixz="0" iyy="1E-07" iyz="0" izz="1E-07"/>
    </inertial>
    <visual>
      <origin xyz="0 0 0" rpy="0 0 0"/>
      <geometry>
        <mesh filename="meshes/right_hip_roll_link_cover.STL"/>
      </geometry>
      <material name="space_gray"/>
    </visual>
  </link>
  <joint name="right_hip_roll_joint_cover" type="fixed">
    <origin xyz="0 0 0" rpy="0 0 0"/>
    <parent link="right_hip_roll_link"/>
    <child link="right_hip_roll_link_cover"/>
  </joint>
  <link name="right_hip_pitch_link">
    <inertial>
      <origin xyz="0.0009793 -0.006908 -0.13908" rpy="0 0 0"/>
      <mass value="5.485"/>
      <inertia ixx="0.040467" ixy="-7.9996E-05" ixz="-0.0011742" iyy="0.041907" iyz="-0.00067304" izz="0.015632"/>
    </inertial>
    <visual>
      <origin xyz="0 0 0" rpy="0 0 0"/>
      <geometry>
        <mesh filename="meshes/right_hip_pitch_link.STL"/>
      </geometry>
      <material name="black"/>
    </visual>
    <!-- <collision>
      <origin xyz="0 0 0" rpy="0 0 0"/>
      <geometry>
        <mesh filename="meshes/right_hip_pitch_link.STL"/>
      </geometry>
    </collision> -->
    <collision>
      <origin xyz="0 0 -0.13" rpy="0 0 0"/>
      <geometry>
        <cylinder radius="0.08" length="0.18"/>
      </geometry>
    </collision>
    <!-- <collision>
      <origin xyz="0 0 -0.04" rpy="0 0 0"/>
      <geometry>
        <sphere radius="0.08"/>
      </geometry>
    </collision> -->
    <!-- <collision>
      <origin xyz="0 0 -0.22" rpy="0 0 0"/>
      <geometry>
        <sphere radius="0.08"/>
      </geometry>
    </collision> -->
  </link>
  <joint name="right_hip_pitch_joint" type="revolute">
    <origin xyz="0.0932 0 0" rpy="0 -0.7854 0"/>
    <parent link="right_hip_roll_link"/>
    <child link="right_hip_pitch_link"/>
    <axis xyz="0 1 0"/>
    <limit lower="-1.5708" upper="0.5236" effort="300" velocity="4.5451"/>
  </joint>
  <link name="right_hip_pitch_link_cover">
    <inertial>
      <origin xyz="0 0 0" rpy="0 0 0"/>
      <mass value="0.0001"/>
      <inertia ixx="1E-07" ixy="0" ixz="0" iyy="1E-07" iyz="0" izz="1E-07"/>
    </inertial>
    <visual>
      <origin xyz="0 0 0" rpy="0 0 0"/>
      <geometry>
        <mesh filename="meshes/right_hip_pitch_link_cover.STL"/>
      </geometry>
      <material name="space_gray"/>
    </visual>
  </link>
  <joint name="right_hip_pitch_joint_cover" type="fixed">
    <origin xyz="0 0 0" rpy="0 0 0"/>
    <parent link="right_hip_pitch_link"/>
    <child link="right_hip_pitch_link_cover"/>
  </joint>
  <link name="right_hip_pitch_link_cover_1">
    <inertial>
      <origin xyz="0 0 0" rpy="0 0 0"/>
      <mass value="0.0001"/>
      <inertia ixx="1E-07" ixy="0" ixz="0" iyy="1E-07" iyz="0" izz="1E-07"/>
    </inertial>
    <visual>
      <origin xyz="0 0 0" rpy="0 0 0"/>
      <geometry>
        <mesh filename="meshes/right_hip_pitch_link_cover_1.STL"/>
      </geometry>
      <material name="black"/>
    </visual>
  </link>
  <joint name="right_hip_pitch_joint_cover_1" type="fixed">
    <origin xyz="0 0 0" rpy="0 0 0"/>
    <parent link="right_hip_pitch_link"/>
    <child link="right_hip_pitch_link_cover_1"/>
  </joint>
  <link name="right_knee_link">
    <inertial>
      <origin xyz="0.003116 0.002172 -0.095939" rpy="0 0 0"/>
      <mass value="4.891"/>
      <inertia ixx="0.048617" ixy="0.00015286" ixz="-0.00151963" iyy="0.05086" iyz="0.00014976" izz="0.006863"/>
    </inertial>
    <visual>
      <origin xyz="0 0 0" rpy="0 0 0"/>
      <geometry>
        <mesh filename="meshes/right_knee_link.STL"/>
      </geometry>
      <material name="black"/>
    </visual>
    <!-- <collision>
      <origin xyz="0 0 0" rpy="0 0 0"/>
      <geometry>
        <mesh filename="meshes/right_knee_link.STL"/>
      </geometry>
    </collision> -->
    <collision>
      <origin xyz="0 0 -0.20" rpy="0 0 0"/>
      <geometry>
        <cylinder radius="0.06" length="0.16"/>
      </geometry>
    </collision>
    <!-- <collision>
      <origin xyz="0 0 -0.12" rpy="0 0 0"/>
      <geometry>
        <sphere radius="0.06"/>
      </geometry>
    </collision> -->
    <!-- <collision>
      <origin xyz="0 0 -0.28" rpy="0 0 0"/>
      <geometry>
        <sphere radius="0.06"/>
      </geometry>
    </collision> -->
  </link>
  <joint name="right_knee_joint" type="revolute">
    <origin xyz="-0.0034097 0.0026122 -0.345" rpy="0 0 0"/>
    <parent link="right_hip_pitch_link"/>
    <child link="right_knee_link"/>
    <axis xyz="0 1 0"/>
    <limit lower="0" upper="1.9199" effort="300" velocity="4.5451"/>
  </joint>
  <link name="right_knee_link_cover">
    <inertial>
      <origin xyz="0 0 0" rpy="0 0 0"/>
      <mass value="0.0001"/>
      <inertia ixx="1E-07" ixy="0" ixz="0" iyy="1E-07" iyz="0" izz="1E-07"/>
    </inertial>
    <visual>
      <origin xyz="0 0 0" rpy="0 0 0"/>
      <geometry>
        <mesh filename="meshes/right_knee_link_cover.STL"/>
      </geometry>
      <material name="space_gray"/>
    </visual>
  </link>
  <joint name="right_knee_joint_cover" type="fixed">
    <origin xyz="0 0 0" rpy="0 0 0"/>
    <parent link="right_knee_link"/>
    <child link="right_knee_link_cover"/>
  </joint>
  <link name="right_ankle_pitch_link">
    <inertial>
      <origin xyz="-0.013123 0.0014062 -0.015406" rpy="0 0 0"/>
      <mass value="0.3104"/>
      <inertia ixx="0.00028737" ixy="-4.49E-08" ixz="0.00016682" iyy="0.00037778" iyz="-3.845E-07" izz="0.00019836"/>
    </inertial>
    <visual>
      <origin xyz="0 0 0" rpy="0 0 0"/>
      <geometry>
        <mesh filename="meshes/right_ankle_pitch_link.STL"/>
      </geometry>
      <material name="silver"/>
    </visual>
    <!-- <collision>
      <origin xyz="0 0 0" rpy="0 0 0"/>
      <geometry>
        <mesh filename="meshes/right_ankle_pitch_link.STL"/>
      </geometry>
    </collision> -->
  </link>
  <joint name="right_ankle_pitch_joint" type="revolute">
    <origin xyz="0.030105 0 -0.33999" rpy="0 0 0"/>
    <parent link="right_knee_link"/>
    <child link="right_ankle_pitch_link"/>
    <axis xyz="0 1 0"/>
    <limit lower="-0.5236" upper="0.87267" effort="100" velocity="8.1812"/>
  </joint>
  <link name="right_ankle_roll_link">
    <inertial>
      <origin xyz="0.02627 -0.00014 -0.02379" rpy="0 0 0"/>
      <mass value="0.7451"/>
      <inertia ixx="0.0013205" ixy="5.3322E-06" ixz="0.00071896" iyy="0.0025285" iyz="-1.549E-07" izz="0.002028"/>
    </inertial>
    <visual>
      <origin xyz="0 0 0" rpy="0 0 0"/>
      <geometry>
        <mesh filename="meshes/right_ankle_roll_link.STL"/>
      </geometry>
      <material name="gray"/>
    </visual>
    <collision>
      <origin xyz="0 0 0" rpy="0 0 0"/>
      <geometry>
        <mesh filename="meshes/right_ankle_roll_collision_link.STL" scale="0.001 0.001 0.001"/>
      </geometry>
    </collision>
  </link>
  <joint name="right_ankle_roll_joint" type="revolute">
    <origin xyz="0 0 0" rpy="0 0.64549 0"/>
    <parent link="right_ankle_pitch_link"/>
    <child link="right_ankle_roll_link"/>
    <axis xyz="0 0 1"/>
    <limit lower="-0.34907" upper="0.34907" effort="100" velocity="8.1812"/>
  </joint>
  <link name="right_toe_pitch_link">
    <inertial>
      <origin xyz="0.0259 2.09E-05 -0.009958" rpy="0 0 0"/>
      <mass value="0.3163"/>
      <inertia ixx="0.0001951" ixy="-1.91E-07" ixz="2.59623E-05" iyy="0.00026895" iyz="-6.018E-09" izz="0.00040482"/>
    </inertial>
    <visual>
      <origin xyz="0 0 0" rpy="0 0 0"/>
      <geometry>
        <mesh filename="meshes/right_toe_pitch_link.STL"/>
      </geometry>
      <material name="black"/>
    </visual>
    <collision>
      <origin xyz="0 0 0" rpy="0 0 0"/>
      <geometry>
        <mesh filename="meshes/right_toe_pitch_collision_link.STL" scale="0.001 0.001 0.001"/>
      </geometry>
    </collision>
  </link>
  <joint name="right_toe_pitch_joint" type="revolute">
    <origin xyz="0.12007 0.0010001 0.013567" rpy="0 -0.64549 0"/>
    <parent link="right_ankle_roll_link"/>
    <child link="right_toe_pitch_link"/>
    <axis xyz="0 1 0"/>
    <limit lower="-1.0472" upper="0.34907" effort="20" velocity="7.0384"/>
  </joint>
  <link name="right_toe_pitch_link_cover">
    <inertial>
      <origin xyz="0 0 0" rpy="0 0 0"/>
      <mass value="0.0001"/>
      <inertia ixx="1E-07" ixy="0" ixz="0" iyy="1E-07" iyz="0" izz="1E-07"/>
    </inertial>
    <visual>
      <origin xyz="0 0 0" rpy="0 0 0"/>
      <geometry>
        <mesh filename="meshes/right_toe_pitch_link_cover.STL"/>
      </geometry>
      <material name="space_gray"/>
    </visual>
  </link>
  <joint name="right_toe_pitch_joint_cover" type="fixed">
    <origin xyz="0 0 0" rpy="0 0 0"/>
    <parent link="right_toe_pitch_link"/>
    <child link="right_toe_pitch_link_cover"/>
  </joint>

  <!-- WAIST -->
  <link name="waist_roll_link">
    <inertial>
      <origin xyz="-0.001959 -7.953E-08 0.040667" rpy="0 0 0"/>
      <mass value="1.461"/>
      <inertia ixx="0.0029089" ixy="1.8321E-11" ixz="-3.536E-06" iyy="0.0024244" iyz="-2.571E-09" izz="0.0026838"/>
    </inertial>
    <visual>
      <origin xyz="0 0 0" rpy="0 0 0"/>
      <geometry>
        <mesh filename="meshes/waist_roll_link.STL"/>
      </geometry>
      <material name="black"/>
    </visual>
    <!-- <collision>
      <origin xyz="0 0 0" rpy="0 0 0"/>
      <geometry>
        <mesh filename="meshes/waist_roll_link.STL"/>
      </geometry>
    </collision> -->
  </link>
  <joint name="waist_roll_joint" type="revolute">
    <origin xyz="0.027786 0 0.074086" rpy="0 0 0"/>
    <parent link="pelvis"/>
    <child link="waist_roll_link"/>
    <axis xyz="1 0 0"/>
    <limit lower="-0.34907" upper="0.34907" effort="120" velocity="2.5133"/>
  </joint>
  <link name="waist_yaw_link">
    <inertial>
      <origin xyz="-0.005028 -1.04E-05 0.0297" rpy="0 0 0"/>
      <mass value="0.869"/>
      <inertia ixx="0.00168934" ixy="7.453E-09" ixz="8.9518E-06" iyy="0.00186511" iyz="3.58E-08" izz="0.00207771"/>
    </inertial>
    <visual>
      <origin xyz="0 0 0" rpy="0 0 0"/>
      <geometry>
        <mesh filename="meshes/waist_yaw_link.STL"/>
      </geometry>
      <material name="black"/>
    </visual>
    <!-- <collision>
      <origin xyz="0 0 0" rpy="0 0 0"/>
      <geometry>
        <mesh filename="meshes/waist_yaw_link.STL"/>
      </geometry>
    </collision> -->
  </link>
  <joint name="waist_yaw_joint" type="revolute">
    <origin xyz="0 0 0.0519" rpy="0 0 0"/>
    <parent link="waist_roll_link"/>
    <child link="waist_yaw_link"/>
    <axis xyz="0 0 1"/>
    <limit lower="-0.5236" upper="0.5236" effort="120" velocity="2.5133"/>
  </joint>
  <link name="waist_yaw_link_cover">
    <inertial>
      <origin xyz="0 0 0" rpy="0 0 0"/>
      <mass value="0.0001"/>
      <inertia ixx="1E-07" ixy="0" ixz="0" iyy="1E-07" iyz="0" izz="1E-07"/>
    </inertial>
    <visual>
      <origin xyz="0 0 0" rpy="0 0 0"/>
      <geometry>
        <mesh filename="meshes/waist_yaw_link_cover.STL"/>
      </geometry>
      <material name="black"/>
    </visual>
  </link>
  <joint name="waist_yaw_joint_cover" type="fixed">
    <origin xyz="0 0 0" rpy="0 0 0"/>
    <parent link="waist_yaw_link"/>
    <child link="waist_yaw_link_cover"/>
  </joint>
  <link name="waist_pitch_link">
    <inertial>
      <origin xyz="-0.06907 0.001639 0.16651" rpy="0 0 0"/>
      <mass value="25.812"/>
      <inertia ixx="0.36892" ixy="-0.0027776" ixz="0.0012006" iyy="0.41161" iyz="-0.0030293" izz="0.28619"/>
    </inertial>
    <visual>
      <origin xyz="0 0 0" rpy="0 0 0"/>
      <geometry>
        <mesh filename="meshes/waist_pitch_link.STL"/>
      </geometry>
      <material name="black"/>
    </visual>
    <!-- <collision>
      <origin xyz="0 0 0" rpy="0 0 0"/>
      <geometry>
        <mesh filename="meshes/waist_pitch_link.STL"/>
      </geometry>
    </collision> -->
    <collision>
      <origin xyz="-0.068 0 0.15" rpy="0 0 0"/>
      <geometry>
        <box size="0.26 0.245 0.32"/>
      </geometry>
    </collision>
  </link>
  <joint name="waist_pitch_joint" type="revolute">
    <origin xyz="0 0 0.061" rpy="0 0 0"/>
    <parent link="waist_yaw_link"/>
    <child link="waist_pitch_link"/>
    <axis xyz="0 1 0"/>
    <limit lower="-0.17453" upper="0.7854" effort="120" velocity="2.5133"/>
  </joint>
  <link name="waist_pitch_link_cover">
    <inertial>
      <origin xyz="0 0 0" rpy="0 0 0"/>
      <mass value="0.0001"/>
      <inertia ixx="1E-07" ixy="0" ixz="0" iyy="1E-07" iyz="0" izz="1E-07"/>
    </inertial>
    <visual>
      <origin xyz="0 0 0" rpy="0 0 0"/>
      <geometry>
        <mesh filename="meshes/waist_pitch_link_cover.STL"/>
      </geometry>
      <material name="space_gray"/>
    </visual>
  </link>
  <joint name="waist_pitch_joint_cover" type="fixed">
    <origin xyz="0 0 0" rpy="0 0 0"/>
    <parent link="waist_pitch_link"/>
    <child link="waist_pitch_link_cover"/>
  </joint>
  <link name="waist_pitch_link_cover_1">
    <inertial>
      <origin xyz="0 0 0" rpy="0 0 0"/>
      <mass value="0.0001"/>
      <inertia ixx="1E-07" ixy="0" ixz="0" iyy="1E-07" iyz="0" izz="1E-07"/>
    </inertial>
    <visual>
      <origin xyz="0 0 0" rpy="0 0 0"/>
      <geometry>
        <mesh filename="meshes/waist_pitch_link_cover_1.STL"/>
      </geometry>
      <material name="black"/>
    </visual>
  </link>
  <joint name="waist_pitch_joint_cover_1" type="fixed">
    <origin xyz="0 0 0" rpy="0 0 0"/>
    <parent link="waist_pitch_link"/>
    <child link="waist_pitch_link_cover_1"/>
  </joint>

  <!-- HEAD -->
  <link name="head_pitch_link">
    <inertial>
      <origin xyz="-0.002737 0.0004272 0.0397864" rpy="0 0 0"/>
      <mass value="0.2676"/>
      <inertia ixx="0.000440415" ixy="4.552E-06" ixz="-5.3182E-05" iyy="0.00041708" iyz="-5.658E-06" izz="0.00032583"/>
    </inertial>
    <visual>
      <origin xyz="0 0 0" rpy="0 0 0"/>
      <geometry>
        <mesh filename="meshes/head_pitch_link.STL"/>
      </geometry>
      <material name="black"/>
    </visual>
    <!-- <collision>
      <origin xyz="0 0 0" rpy="0 0 0"/>
      <geometry>
        <mesh filename="meshes/head_pitch_link.STL"/>
      </geometry>
    </collision> -->
  </link>
  <joint name="head_pitch_joint" type="revolute">
    <origin xyz="-0.0165 0 0.3285" rpy="0 0 0"/>
    <parent link="waist_pitch_link"/>
    <child link="head_pitch_link"/>
    <axis xyz="0 1 0"/>
    <limit lower="-0.29671" upper="0.7854" effort="8.3" velocity="32.5"/>
  </joint>
  <link name="head_pitch_link_cover">
    <inertial>
      <origin xyz="0 0 0" rpy="0 0 0"/>
      <mass value="0.0001"/>
      <inertia ixx="1E-07" ixy="0" ixz="0" iyy="1E-07" iyz="0" izz="1E-07"/>
    </inertial>
    <visual>
      <origin xyz="0 0 0" rpy="0 0 0"/>
      <geometry>
        <mesh filename="meshes/head_pitch_link_cover.STL"/>
      </geometry>
      <material name="black"/>
    </visual>
  </link>
  <joint name="head_pitch_joint_cover" type="fixed">
    <origin xyz="0 0 0" rpy="0 0 0"/>
    <parent link="head_pitch_link"/>
    <child link="head_pitch_link_cover"/>
  </joint>
  <link name="head_yaw_link">
    <inertial>
      <origin xyz="-0.0028466 4.906E-05 0.083016" rpy="0 0 0"/>
      <mass value="3.414"/>
      <inertia ixx="0.00936047" ixy="-5.56656E-05" ixz="0.00025039" iyy="0.01286849" iyz="4.8895E-07" izz="0.00932231"/>
    </inertial>
    <visual>
      <origin xyz="0 0 0" rpy="0 0 0"/>
      <geometry>
        <mesh filename="meshes/head_yaw_link.STL"/>
      </geometry>
      <material name="black"/>
    </visual>
    <!-- <collision>
      <origin xyz="0 0 0" rpy="0 0 0"/>
      <geometry>
        <mesh filename="meshes/head_yaw_link.STL"/>
      </geometry>
    </collision> -->
    <collision>
      <origin xyz="0 0 0.08" rpy="0 0 0"/>
      <geometry>
        <sphere radius="0.1"/>
      </geometry>
    </collision>
  </link>
  <joint name="head_yaw_joint" type="revolute">
    <origin xyz="-0.005 0 0.087" rpy="0 0 0"/>
    <parent link="head_pitch_link"/>
    <child link="head_yaw_link"/>
    <axis xyz="0 0 1"/>
    <limit lower="-1.22" upper="1.22" effort="3" velocity="44"/>
  </joint>
  <link name="head_yaw_link_cover">
    <inertial>
      <origin xyz="0 0 0" rpy="0 0 0"/>
      <mass value="0.0001"/>
      <inertia ixx="1E-07" ixy="0" ixz="0" iyy="1E-07" iyz="0" izz="1E-07"/>
    </inertial>
    <visual>
      <origin xyz="0 0 0" rpy="0 0 0"/>
      <geometry>
        <mesh filename="meshes/head_yaw_link_cover.STL"/>
      </geometry>
      <material name="black"/>
    </visual>
  </link>
  <joint name="head_yaw_joint_cover" type="fixed">
    <origin xyz="0 0 0" rpy="0 0 0"/>
    <parent link="head_yaw_link"/>
    <child link="head_yaw_link_cover"/>
  </joint>

  <!-- zed -->
  <link name="zed_link">
  </link>
  <joint name="zed_joint" type="fixed">
    <origin xyz="0.0405855 2.4789e-8 0.1161820" rpy="0 0 0"/>
    <parent link="head_yaw_link"/>
    <child link="zed_link"/>
  </joint>

  <!-- os0 -->
  <link name="os0_link">
  </link>
  <joint name="os0_joint" type="fixed">
    <origin xyz="0.0363995 0 0.04765" rpy="0 0 0"/>
    <parent link="head_yaw_link"/>
    <child link="os0_link"/>
  </joint>

  <!-- LEFT ARM -->
  <link name="left_shoulder_pitch_link">
    <inertial>
      <origin xyz="-0.0032162 0.070854 -1.8641E-05" rpy="0 0 0"/>
      <mass value="2.8978"/>
      <inertia ixx="0.0050622" ixy="0.00020336" ixz="-8.055E-07" iyy="0.0029245" iyz="-4.1107E-06" izz="0.0032125"/>
    </inertial>
    <visual>
      <origin xyz="0 0 0" rpy="0 0 0"/>
      <geometry>
        <mesh filename="meshes/left_shoulder_pitch_link.STL"/>
      </geometry>
      <material name="space_gray"/>
    </visual>
    <!-- <collision>
      <origin xyz="0 0 0" rpy="0 0 0"/>
      <geometry>
        <mesh filename="meshes/left_shoulder_pitch_link.STL"/>
      </geometry>
    </collision> -->
  </link>
  <joint name="left_shoulder_pitch_joint" type="revolute">
    <origin xyz="-0.012869 0.12432 0.24937" rpy="0.034874 -0.032193 -0.055261"/>
    <parent link="waist_pitch_link"/>
    <child link="left_shoulder_pitch_link"/>
    <axis xyz="0 1 0"/>
    <limit lower="-3.142" upper="0.873" effort="100" velocity="23"/>
  </joint>
  <link name="left_shoulder_pitch_link_cover">
    <inertial>
      <origin xyz="0 0 0" rpy="0 0 0"/>
      <mass value="0.0001"/>
      <inertia ixx="1E-07" ixy="0" ixz="0" iyy="1E-07" iyz="0" izz="1E-07"/>
    </inertial>
    <visual>
      <origin xyz="0 0 0" rpy="0 0 0"/>
      <geometry>
        <mesh filename="meshes/left_shoulder_pitch_link_cover.STL"/>
      </geometry>
      <material name="black"/>
    </visual>
    <!-- <collision>
      <origin xyz="0 0 0" rpy="0 0 0"/>
      <geometry>
        <mesh filename="meshes/left_shoulder_pitch_link_cover.STL"/>
      </geometry>
    </collision> -->
  </link>
  <joint name="left_shoulder_pitch_joint_cover" type="fixed">
    <origin xyz="0 0 0" rpy="0 0 0"/>
    <parent link="left_shoulder_pitch_link"/>
    <child link="left_shoulder_pitch_link_cover"/>
  </joint>
  <link name="left_shoulder_roll_link">
    <inertial>
      <origin xyz="0.00631152592679313 -0.0016691190565805 -0.0693040915206086" rpy="0 0 0"/>
      <mass value="2.07581421994951"/>
      <inertia ixx="0.00348307566752284" ixy="-4.25802214000036E-05" ixz="-0.000592391367719154" iyy="0.00370763943814611" iyz="-0.0001031826561485" izz="0.00321823825904744"/>
    </inertial>
    <visual>
      <origin xyz="0 0 0" rpy="0 0 0"/>
      <geometry>
        <mesh filename="meshes/left_shoulder_roll_link.STL"/>
      </geometry>
      <material name="space_gray"/>
    </visual>
    <!-- <collision>
      <origin xyz="0 0 0" rpy="0 0 0"/>
      <geometry>
        <mesh filename="meshes/left_shoulder_roll_link.STL"/>
      </geometry>
    </collision> -->
    <collision>
      <origin xyz="0 0 -0.085" rpy="0 0 0"/>
      <geometry>
        <cylinder radius="0.055" length="0.17"/>
      </geometry>
    </collision>
  </link>
  <joint name="left_shoulder_roll_joint" type="revolute">
    <origin xyz="-0.00055 0.08 0" rpy="-0.034907 0 0"/>
    <parent link="left_shoulder_pitch_link"/>
    <child link="left_shoulder_roll_link"/>
    <axis xyz="1 0 0"/>
    <limit lower="-0.262" upper="3.054" effort="100" velocity="23"/>
  </joint>
  <link name="left_shoulder_roll_link_cover">
    <inertial>
      <origin xyz="0 0 0" rpy="0 0 0"/>
      <mass value="0.0001"/>
      <inertia ixx="1E-07" ixy="0" ixz="0" iyy="1E-07" iyz="0" izz="1E-07"/>
    </inertial>
    <visual>
      <origin xyz="0 0 0" rpy="0 0 0"/>
      <geometry>
        <mesh filename="meshes/left_shoulder_roll_link_cover.STL"/>
      </geometry>
      <material name="black"/>
    </visual>
    <!-- <collision>
      <origin xyz="0 0 0" rpy="0 0 0"/>
      <geometry>
        <mesh filename="meshes/left_shoulder_roll_link_cover.STL"/>
      </geometry>
    </collision> -->
  </link>
  <joint name="left_shoulder_roll_joint_cover" type="fixed">
    <origin xyz="0 0 0" rpy="0 0 0"/>
    <parent link="left_shoulder_roll_link"/>
    <child link="left_shoulder_roll_link_cover"/>
  </joint>
  <link name="left_shoulder_yaw_link">
    <inertial>
      <origin xyz="-0.00168841938198394 0.00198321072488372 -0.0486133477774624" rpy="0 0 0"/>
      <mass value="1.72700766977071"/>
      <inertia ixx="0.00172415389809702" ixy="-1.44198015690642E-07" ixz="-3.53659555964234E-05" iyy="0.00238011280314875" iyz="-4.09574403786463E-05" izz="0.00151162652464852"/>
    </inertial>
    <visual>
      <origin xyz="0 0 0" rpy="0 0 0"/>
      <geometry>
        <mesh filename="meshes/left_shoulder_yaw_link.STL"/>
      </geometry>
      <material name="space_gray"/>
    </visual>
    <!-- <collision>
      <origin xyz="0 0 0" rpy="0 0 0"/>
      <geometry>
        <mesh filename="meshes/left_shoulder_yaw_link.STL"/>
      </geometry>
    </collision> -->
  </link>
  <joint name="left_shoulder_yaw_joint" type="revolute">
    <origin xyz="0 0 -0.13045" rpy="0 0 0"/>
    <parent link="left_shoulder_roll_link"/>
    <child link="left_shoulder_yaw_link"/>
    <axis xyz="0 0 1"/>
    <limit lower="-1.658" upper="1.658" effort="53" velocity="24.6"/>
  </joint>
  <link name="left_shoulder_yaw_link_cover">
    <inertial>
      <origin xyz="0 0 0" rpy="0 0 0"/>
      <mass value="0.0001"/>
      <inertia ixx="1E-07" ixy="0" ixz="0" iyy="1E-07" iyz="0" izz="1E-07"/>
    </inertial>
    <visual>
      <origin xyz="0 0 0" rpy="0 0 0"/>
      <geometry>
        <mesh filename="meshes/left_shoulder_yaw_link_cover.STL"/>
      </geometry>
      <material name="black"/>
    </visual>
    <!-- <collision>
      <origin xyz="0 0 0" rpy="0 0 0"/>
      <geometry>
        <mesh filename="meshes/left_shoulder_yaw_link_cover.STL"/>
      </geometry>
    </collision> -->
  </link>
  <joint name="left_shoulder_yaw_joint_cover" type="fixed">
    <origin xyz="0 0 0" rpy="0 0 0"/>
    <parent link="left_shoulder_yaw_link"/>
    <child link="left_shoulder_yaw_link_cover"/>
  </joint>
  <link name="left_elbow_link">
    <inertial>
      <origin xyz="-0.0009947943141147 -9.79600915894246E-05 -0.0519448559142559" rpy="0 0 0"/>
      <mass value="1.50518609772073"/>
      <inertia ixx="0.00100158768267505" ixy="3.77858880985766E-06" ixz="1.95397065175749E-05" iyy="0.000817296975324865" iyz="1.37794820941889E-05" izz="0.00138163565799029"/>
    </inertial>
    <visual>
      <origin xyz="0 0 0" rpy="0 0 0"/>
      <geometry>
        <mesh filename="meshes/left_elbow_link.STL"/>
      </geometry>
      <material name="space_gray"/>
    </visual>
    <!-- <collision>
      <origin xyz="0 0 0" rpy="0 0 0"/>
      <geometry>
        <mesh filename="meshes/left_elbow_link.STL"/>
      </geometry>
    </collision> -->
    <collision>
      <origin xyz="0 0 -0.125" rpy="0 0 0"/>
      <geometry>
        <cylinder radius="0.045" length="0.12"/>
      </geometry>
    </collision>
  </link>
  <joint name="left_elbow_joint" type="revolute">
    <origin xyz="0 0 -0.124" rpy="0 0 0"/>
    <parent link="left_shoulder_yaw_link"/>
    <child link="left_elbow_link"/>
    <axis xyz="0 1 0"/>
    <limit lower="-1.658" upper="0.175" effort="53" velocity="24.6"/>
  </joint>
  <link name="left_elbow_link_cover">
    <inertial>
      <origin xyz="0 0 0" rpy="0 0 0"/>
      <mass value="0.0001"/>
      <inertia ixx="1E-07" ixy="0" ixz="0" iyy="1E-07" iyz="0" izz="1E-07"/>
    </inertial>
    <visual>
      <origin xyz="0 0 0" rpy="0 0 0"/>
      <geometry>
        <mesh filename="meshes/left_elbow_link_cover.STL"/>
      </geometry>
      <material name="black"/>
    </visual>
    <!-- <collision>
      <origin xyz="0 0 0" rpy="0 0 0"/>
      <geometry>
        <mesh filename="meshes/left_elbow_link_cover.STL"/>
      </geometry>
    </collision> -->
  </link>
  <joint name="left_elbow_joint_cover" type="fixed">
    <origin xyz="0 0 0" rpy="0 0 0"/>
    <parent link="left_elbow_link"/>
    <child link="left_elbow_link_cover"/>
  </joint>
  <link name="left_wrist_yaw_link">
    <inertial>
      <origin xyz="8.7414E-06 -0.00076707 -0.031405" rpy="0 0 0"/>
      <mass value="0.66942"/>
      <inertia ixx="0.00040364" ixy="-2.8043E-08" ixz="-4.1761E-08" iyy="0.00047527" iyz="9.7472E-06" izz="0.00037088"/>
    </inertial>
    <visual>
      <origin xyz="0 0 0" rpy="0 0 0"/>
      <geometry>
        <mesh filename="meshes/left_wrist_yaw_link.STL"/>
      </geometry>
      <material name="space_gray"/>
    </visual>
    <!-- <collision>
      <origin xyz="0 0 0" rpy="0 0 0"/>
      <geometry>
        <mesh filename="meshes/left_wrist_yaw_link.STL"/>
      </geometry>
    </collision> -->
  </link>
  <joint name="left_wrist_yaw_joint" type="revolute">
    <origin xyz="0 0 -0.1085" rpy="0 0 0"/>
    <parent link="left_elbow_link"/>
    <child link="left_wrist_yaw_link"/>
    <axis xyz="0 0 1"/>
    <limit lower="-1.745" upper="1.745" effort="30" velocity="15.71"/>
  </joint>
  <link name="left_wrist_yaw_link_cover">
    <inertial>
      <origin xyz="0 0 0" rpy="0 0 0"/>
      <mass value="0.0001"/>
      <inertia ixx="1E-07" ixy="0" ixz="0" iyy="1E-07" iyz="0" izz="1E-07"/>
    </inertial>
    <visual>
      <origin xyz="0 0 0" rpy="0 0 0"/>
      <geometry>
        <mesh filename="meshes/left_wrist_yaw_link_cover.STL"/>
      </geometry>
      <material name="black"/>
    </visual>
    <!-- <collision>
      <origin xyz="0 0 0" rpy="0 0 0"/>
      <geometry>
        <mesh filename="meshes/left_wrist_yaw_link_cover.STL"/>
      </geometry>
    </collision> -->
  </link>
  <joint name="left_wrist_yaw_joint_cover" type="fixed">
    <origin xyz="0 0 0" rpy="0 0 0"/>
    <parent link="left_wrist_yaw_link"/>
    <child link="left_wrist_yaw_link_cover"/>
  </joint>
  <link name="left_wrist_roll_link">
    <inertial>
      <origin xyz="6.13701555671753E-05 6.13696915808259E-05 -0.00599999792673296" rpy="0 0 0"/>
      <mass value="0.0150108867051741"/>
      <inertia ixx="8.39497136265045E-07" ixy="5.6510261665869E-11" ixz="5.52732022941259E-09" iyy="8.39497124427932E-07" iyz="-5.5272732079962E-09" izz="2.631344947001E-07"/>
    </inertial>
    <visual>
      <origin xyz="0 0 0" rpy="0 0 0"/>
      <geometry>
        <mesh filename="meshes/left_wrist_roll_link.STL"/>
      </geometry>
      <material name="space_gray"/>
    </visual>
    <!-- <collision>
      <origin xyz="0 0 0" rpy="0 0 0"/>
      <geometry>
        <mesh filename="meshes/left_wrist_roll_link.STL"/>
      </geometry>
    </collision> -->
  </link>
  <joint name="left_wrist_roll_joint" type="revolute">
    <origin xyz="0 0.017 -0.113" rpy="0 0 0"/>
    <parent link="left_wrist_yaw_link"/>
    <child link="left_wrist_roll_link"/>
    <axis xyz="1 0 0"/>
    <limit lower="-0.925" upper="0.541" effort="7" velocity="288.9"/>
  </joint>
  <link name="left_wrist_pitch_link">
    <inertial>
      <origin xyz="5.59535506325926E-05 -0.0131920194438887 -0.0141057590067551" rpy="0 0 0"/>
      <mass value="0.0505176966638041"/>
      <inertia ixx="7.08890658167585E-06" ixy="3.14949821344518E-08" ixz="1.15863363392752E-08" iyy="9.24502638301866E-06" iyz="-7.52640779017685E-07" izz="1.48011283866283E-05"/>
    </inertial>
    <visual>
      <origin xyz="0 0 0" rpy="0 0 0"/>
      <geometry>
        <mesh filename="meshes/left_wrist_pitch_link.STL"/>
      </geometry>
      <material name="space_gray"/>
    </visual>
    <!-- <collision>
      <origin xyz="0 0 0" rpy="0 0 0"/>
      <geometry>
        <mesh filename="meshes/left_wrist_pitch_link.STL"/>
      </geometry>
    </collision> -->
  </link>
  <joint name="left_wrist_pitch_joint" type="revolute">
    <origin xyz="0 -0.0054 -0.012" rpy="0 0 0"/>
    <parent link="left_wrist_roll_link"/>
    <child link="left_wrist_pitch_link"/>
    <axis xyz="0 1 0"/>
    <limit lower="-1.047" upper="1.047" effort="7" velocity="288.9"/>
  </joint>

  <!-- RIGHT ARM -->
  <link name="right_shoulder_pitch_link">
    <inertial>
      <origin xyz="-0.0031655 -0.070765 3.7134E-05" rpy="0 0 0"/>
      <mass value="2.9012"/>
      <inertia ixx="0.0050623" ixy="-0.00020339" ixz="-8.2513E-07" iyy="0.0029246" iyz="4.0396E-06" izz="0.0032125"/>
    </inertial>
    <visual>
      <origin xyz="0 0 0" rpy="0 0 0"/>
      <geometry>
        <mesh filename="meshes/right_shoulder_pitch_link.STL"/>
      </geometry>
      <material name="space_gray"/>
    </visual>
    <!-- <collision>
      <origin xyz="0 0 0" rpy="0 0 0"/>
      <geometry>
        <mesh filename="meshes/right_shoulder_pitch_link.STL"/>
      </geometry>
    </collision> -->
  </link>
  <joint name="right_shoulder_pitch_joint" type="revolute">
    <origin xyz="-0.012869 -0.12432 0.24937" rpy="-0.034873 -0.032193 0.055261"/>
    <parent link="waist_pitch_link"/>
    <child link="right_shoulder_pitch_link"/>
    <axis xyz="0 1 0"/>
    <limit lower="-3.142" upper="0.873" effort="100" velocity="23"/>
  </joint>
  <link name="right_shoulder_pitch_link_cover">
    <inertial>
      <origin xyz="0 0 0" rpy="0 0 0"/>
      <mass value="0.0001"/>
      <inertia ixx="1E-07" ixy="0" ixz="0" iyy="1E-07" iyz="0" izz="1E-07"/>
    </inertial>
    <visual>
      <origin xyz="0 0 0" rpy="0 0 0"/>
      <geometry>
        <mesh filename="meshes/right_shoulder_pitch_link_cover.STL"/>
      </geometry>
      <material name="black"/>
    </visual>
    <!-- <collision>
      <origin xyz="0 0 0" rpy="0 0 0"/>
      <geometry>
        <mesh filename="meshes/right_shoulder_pitch_link_cover.STL"/>
      </geometry>
    </collision> -->
  </link>
  <joint name="right_shoulder_pitch_joint_cover" type="fixed">
    <origin xyz="0 0 0" rpy="0 0 0"/>
    <parent link="right_shoulder_pitch_link"/>
    <child link="right_shoulder_pitch_link_cover"/>
  </joint>
  <link name="right_shoulder_roll_link">
    <inertial>
      <origin xyz="0.00630055179748046 0.00167224635640145 -0.0693024385969429" rpy="0 0 0"/>
      <mass value="2.07586995654268"/>
      <inertia ixx="0.00348219274231314" ixy="4.13321161627876E-05" ixz="-0.000592605923081558" iyy="0.00370889971950642" iyz="0.000103279293727367" izz="0.00321828671159333"/>
    </inertial>
    <visual>
      <origin xyz="0 0 0" rpy="0 0 0"/>
      <geometry>
        <mesh filename="meshes/right_shoulder_roll_link.STL"/>
      </geometry>
      <material name="space_gray"/>
    </visual>
    <!-- <collision>
      <origin xyz="0 0 0" rpy="0 0 0"/>
      <geometry>
        <mesh filename="meshes/right_shoulder_roll_link.STL"/>
      </geometry>
    </collision> -->
    <collision>
      <origin xyz="0 0 -0.085" rpy="0 0 0"/>
      <geometry>
        <cylinder radius="0.055" length="0.17"/>
      </geometry>
    </collision>
  </link>
  <joint name="right_shoulder_roll_joint" type="revolute">
    <origin xyz="-0.00055 -0.08 0" rpy="0.034907 0 0"/>
    <parent link="right_shoulder_pitch_link"/>
    <child link="right_shoulder_roll_link"/>
    <axis xyz="1 0 0"/>
    <limit lower="-3.054" upper="0.262" effort="100" velocity="23"/>
  </joint>
  <link name="right_shoulder_roll_link_cover">
    <inertial>
      <origin xyz="0 0 0" rpy="0 0 0"/>
      <mass value="0.0001"/>
      <inertia ixx="1E-07" ixy="0" ixz="0" iyy="1E-07" iyz="0" izz="1E-07"/>
    </inertial>
    <visual>
      <origin xyz="0 0 0" rpy="0 0 0"/>
      <geometry>
        <mesh filename="meshes/right_shoulder_roll_link_cover.STL"/>
      </geometry>
      <material name="black"/>
    </visual>
    <!-- <collision>
      <origin xyz="0 0 0" rpy="0 0 0"/>
      <geometry>
        <mesh filename="meshes/right_shoulder_roll_link_cover.STL"/>
      </geometry>
    </collision> -->
  </link>
  <joint name="right_shoulder_roll_joint_cover" type="fixed">
    <origin xyz="0 0 0" rpy="0 0 0"/>
    <parent link="right_shoulder_roll_link"/>
    <child link="right_shoulder_roll_link_cover"/>
  </joint>
  <link name="right_shoulder_yaw_link">
    <inertial>
      <origin xyz="-0.00165143257763506 -0.00198303468476618 -0.0488347493778769" rpy="0 0 0"/>
      <mass value="1.72701258794391"/>
      <inertia ixx="0.00172425007060141" ixy="5.35318420387213E-07" ixz="-3.60168576797043E-05" iyy="0.00238010836512957" iyz="4.08169013781126E-05" izz="0.00151156535344309"/>
    </inertial>
    <visual>
      <origin xyz="0 0 0" rpy="0 0 0"/>
      <geometry>
        <mesh filename="meshes/right_shoulder_yaw_link.STL"/>
      </geometry>
      <material name="space_gray"/>
    </visual>
    <!-- <collision>
      <origin xyz="0 0 0" rpy="0 0 0"/>
      <geometry>
        <mesh filename="meshes/right_shoulder_yaw_link.STL"/>
      </geometry>
    </collision> -->
  </link>
  <joint name="right_shoulder_yaw_joint" type="revolute">
    <origin xyz="0 0 -0.13045" rpy="0 0 0"/>
    <parent link="right_shoulder_roll_link"/>
    <child link="right_shoulder_yaw_link"/>
    <axis xyz="0 0 1"/>
    <limit lower="-1.658" upper="1.658" effort="53" velocity="24.6"/>
  </joint>
  <link name="right_shoulder_yaw_link_cover">
    <inertial>
      <origin xyz="0 0 0" rpy="0 0 0"/>
      <mass value="0.0001"/>
      <inertia ixx="1E-07" ixy="0" ixz="0" iyy="1E-07" iyz="0" izz="1E-07"/>
    </inertial>
    <visual>
      <origin xyz="0 0 0" rpy="0 0 0"/>
      <geometry>
        <mesh filename="meshes/right_shoulder_yaw_link_cover.STL"/>
      </geometry>
      <material name="black"/>
    </visual>
    <!-- <collision>
      <origin xyz="0 0 0" rpy="0 0 0"/>
      <geometry>
        <mesh filename="meshes/right_shoulder_yaw_link_cover.STL"/>
      </geometry>
    </collision> -->
  </link>
  <joint name="right_shoulder_yaw_joint_cover" type="fixed">
    <origin xyz="0 0 0" rpy="0 0 0"/>
    <parent link="right_shoulder_yaw_link"/>
    <child link="right_shoulder_yaw_link_cover"/>
  </joint>
  <link name="right_elbow_link">
    <inertial>
      <origin xyz="-0.00114648786001353 0.000168965128814369 -0.0516602885206988" rpy="0 0 0"/>
      <mass value="1.49705351308511"/>
      <inertia ixx="0.00099514460454227" ixy="-1.36089712280933E-07" ixz="1.89329165829265E-05" iyy="0.000810908635934364" iyz="-1.38486801830574E-05" izz="0.00136842561155971"/>
    </inertial>
    <visual>
      <origin xyz="0 0 0" rpy="0 0 0"/>
      <geometry>
        <mesh filename="meshes/right_elbow_link.STL"/>
      </geometry>
      <material name="space_gray"/>
    </visual>
    <!-- <collision>
      <origin xyz="0 0 0" rpy="0 0 0"/>
      <geometry>
        <mesh filename="meshes/right_elbow_link.STL"/>
      </geometry>
    </collision> -->
    <collision>
      <origin xyz="0 0 -0.125" rpy="0 0 0"/>
      <geometry>
        <cylinder radius="0.045" length="0.12"/>
      </geometry>
    </collision>
  </link>
  <joint name="right_elbow_joint" type="revolute">
    <origin xyz="0 0 -0.124" rpy="0 0 0"/>
    <parent link="right_shoulder_yaw_link"/>
    <child link="right_elbow_link"/>
    <axis xyz="0 1 0"/>
    <limit lower="-1.658" upper="0.175" effort="53" velocity="24.6"/>
  </joint>
  <link name="right_elbow_link_cover">
    <inertial>
      <origin xyz="0 0 0" rpy="0 0 0"/>
      <mass value="0.0001"/>
      <inertia ixx="1E-07" ixy="0" ixz="0" iyy="1E-07" iyz="0" izz="1E-07"/>
    </inertial>
    <visual>
      <origin xyz="0 0 0" rpy="0 0 0"/>
      <geometry>
        <mesh filename="meshes/right_elbow_link_cover.STL"/>
      </geometry>
      <material name="black"/>
    </visual>
    <!-- <collision>
      <origin xyz="0 0 0" rpy="0 0 0"/>
      <geometry>
        <mesh filename="meshes/right_elbow_link_cover.STL"/>
      </geometry>
    </collision> -->
  </link>
  <joint name="right_elbow_joint_cover" type="fixed">
    <origin xyz="0 0 0" rpy="0 0 0"/>
    <parent link="right_elbow_link"/>
    <child link="right_elbow_link_cover"/>
  </joint>
  <link name="right_wrist_yaw_link">
    <inertial>
      <origin xyz="-2.69049601233085E-05 0.000769789365295204 -0.0314033743829218" rpy="0 0 0"/>
      <mass value="0.669507959758961"/>
      <inertia ixx="0.000403607198862523" ixy="5.21628711965564E-08" ixz="4.21823875520562E-08" iyy="0.000475322808409864" iyz="-9.76039692623422E-06" izz="0.000370875961743554"/>
    </inertial>
    <visual>
      <origin xyz="0 0 0" rpy="0 0 0"/>
      <geometry>
        <mesh filename="meshes/right_wrist_yaw_link.STL"/>
      </geometry>
      <material name="space_gray"/>
    </visual>
    <!-- <collision>
      <origin xyz="0 0 0" rpy="0 0 0"/>
      <geometry>
        <mesh filename="meshes/right_wrist_yaw_link.STL"/>
      </geometry>
    </collision> -->
  </link>
  <joint name="right_wrist_yaw_joint" type="revolute">
    <origin xyz="0 0 -0.1085" rpy="0 0 0"/>
    <parent link="right_elbow_link"/>
    <child link="right_wrist_yaw_link"/>
    <axis xyz="0 0 1"/>
    <limit lower="-1.745" upper="1.745" effort="30" velocity="15.71"/>
  </joint>
  <link name="right_wrist_yaw_link_cover">
    <inertial>
      <origin xyz="0 0 0" rpy="0 0 0"/>
      <mass value="0.0001"/>
      <inertia ixx="1E-07" ixy="0" ixz="0" iyy="1E-07" iyz="0" izz="1E-07"/>
    </inertial>
    <visual>
      <origin xyz="0 0 0" rpy="0 0 0"/>
      <geometry>
        <mesh filename="meshes/right_wrist_yaw_link_cover.STL"/>
      </geometry>
      <material name="black"/>
    </visual>
    <!-- <collision>
      <origin xyz="0 0 0" rpy="0 0 0"/>
      <geometry>
        <mesh filename="meshes/right_wrist_yaw_link_cover.STL"/>
      </geometry>
    </collision> -->
  </link>
  <joint name="right_wrist_yaw_joint_cover" type="fixed">
    <origin xyz="0 0 0" rpy="0 0 0"/>
    <parent link="right_wrist_yaw_link"/>
    <child link="right_wrist_yaw_link_cover"/>
  </joint>
  <link name="right_wrist_roll_link">
    <inertial>
      <origin xyz="6.13701553343615E-05 6.13696920221951E-05 -0.00599999792828493" rpy="0 0 0"/>
      <mass value="0.0150108866989409"/>
      <inertia ixx="8.39497136141999E-07" ixy="5.65102590863073E-11" ixz="5.52732023064941E-09" iyy="8.39497124324571E-07" iyz="-5.52727326632826E-09" izz="2.6313449467642E-07"/>
    </inertial>
    <visual>
      <origin xyz="0 0 0" rpy="0 0 0"/>
      <geometry>
        <mesh filename="meshes/right_wrist_roll_link.STL"/>
      </geometry>
      <material name="space_gray"/>
    </visual>
    <!-- <collision>
      <origin xyz="0 0 0" rpy="0 0 0"/>
      <geometry>
        <mesh filename="meshes/right_wrist_roll_link.STL"/>
      </geometry>
    </collision> -->
  </link>
  <joint name="right_wrist_roll_joint" type="revolute">
    <origin xyz="0 -0.017 -0.113" rpy="0 0 0"/>
    <parent link="right_wrist_yaw_link"/>
    <child link="right_wrist_roll_link"/>
    <axis xyz="1 0 0"/>
    <limit lower="-0.541" upper="0.925" effort="7" velocity="288.9"/>
  </joint>
  <link name="right_wrist_pitch_link">
    <inertial>
      <origin xyz="-5.59530866294233E-05 0.0131920193852637 -0.0141057587672804" rpy="0 0 0"/>
      <mass value="0.0505176962698213"/>
      <inertia ixx="7.08890687429645E-06" ixy="3.14959007237179E-08" ixz="-1.15862574457891E-08" iyy="9.24502648612833E-06" iyz="7.52640988343457E-07" izz="1.4801128403098E-05"/>
    </inertial>
    <visual>
      <origin xyz="0 0 0" rpy="0 0 0"/>
      <geometry>
        <mesh filename="meshes/right_wrist_pitch_link.STL"/>
      </geometry>
      <material name="space_gray"/>
    </visual>
    <!-- <collision>
      <origin xyz="0 0 0" rpy="0 0 0"/>
      <geometry>
        <mesh filename="meshes/right_wrist_pitch_link.STL"/>
      </geometry>
    </collision> -->
  </link>
  <joint name="right_wrist_pitch_joint" type="revolute">
    <origin xyz="0 0.0054 -0.012" rpy="0 0 0"/>
    <parent link="right_wrist_roll_link"/>
    <child link="right_wrist_pitch_link"/>
    <axis xyz="0 1 0"/>
    <limit lower="-1.047" upper="1.047" effort="7" velocity="288.9"/>
  </joint>

</robot>
